Loading pytorch-gpu/py3/1.6.0
  Loading requirement: gcc/8.3.1 cuda/10.2 nccl/2.6.4-1-cuda
    cudnn/7.6.5.32-cuda-10.2 intel-mkl/2020.1 magma/2.5.3-cuda
    openmpi/4.0.2-cuda
+ python3 -u run_resutls.py
Traceback (most recent call last):
  File "run_resutls.py", line 758, in <module>
    is_encoder_struct=True)
  File "run_resutls.py", line 189, in run_exp_extraction_and_visualization_custom_BK
    bin_after_GMP=bin_after_GMP)
  File "run_resutls.py", line 471, in run_viz_expes
    contrastive_loss=contrastive_loss, encoder_struct=True, Hmg_dst=True, z_struct_size=z_struct_size)
  File "/gpfsdswork/projects/rech/rjg/uiu23ko/Thesis/Pytorch_vanilla_Beta_VAE/visualizer_CNN.py", line 1910, in plot_resume
    fig.savefig(path_save)
  File "/gpfslocalsup/pub/anaconda-py3/2020.02/envs/pytorch-gpu-1.6.0/lib/python3.7/site-packages/matplotlib/figure.py", line 2311, in savefig
    self.canvas.print_figure(fname, **kwargs)
  File "/gpfslocalsup/pub/anaconda-py3/2020.02/envs/pytorch-gpu-1.6.0/lib/python3.7/site-packages/matplotlib/backend_bases.py", line 2217, in print_figure
    **kwargs)
  File "/gpfslocalsup/pub/anaconda-py3/2020.02/envs/pytorch-gpu-1.6.0/lib/python3.7/site-packages/matplotlib/backend_bases.py", line 1639, in wrapper
    return func(*args, **kwargs)
  File "/gpfslocalsup/pub/anaconda-py3/2020.02/envs/pytorch-gpu-1.6.0/lib/python3.7/site-packages/matplotlib/backends/backend_agg.py", line 512, in print_png
    dpi=self.figure.dpi, metadata=metadata, pil_kwargs=pil_kwargs)
  File "/gpfslocalsup/pub/anaconda-py3/2020.02/envs/pytorch-gpu-1.6.0/lib/python3.7/site-packages/matplotlib/image.py", line 1591, in imsave
    image.save(fname, **pil_kwargs)
  File "/gpfslocalsup/pub/anaconda-py3/2020.02/envs/pytorch-gpu-1.6.0/lib/python3.7/site-packages/PIL/Image.py", line 2155, in save
    fp = builtins.open(filename, "w+b")
FileNotFoundError: [Errno 2] No such file or directory: 'fig_results/resume/plot_resume_mnist_ES_binary_10_test.png'
+ wait
+ echo 'All done !'
