Loading pytorch-gpu/py3/1.6.0
  Loading requirement: gcc/8.3.1 cuda/10.2 nccl/2.6.4-1-cuda
    cudnn/7.6.5.32-cuda-10.2 intel-mkl/2020.1 magma/2.5.3-cuda
    openmpi/4.0.2-cuda
++ sed -n 85p parameters_combinations/mnist_classifier_ratio.txt
+ LINE='--gpu_devices 0 --max_iter 100 --batch_size 32 --lr 1e-3 --use_scheduler True --is_VAE_var True --z_var_size 15 --lambda_BCE 1 --beta 1 --var_second_cnn_block True --var_third_cnn_block False --encoder_var_name mnist_vae_var_2cb_15_classifier_grad_inv_PT_new --freeze_Encoder True --PT_model True --PT_model_EV_classifier True --exp_name mnist_vae_var_2cb_15_grad_inv_PT_new'
+ echo --gpu_devices 0 --max_iter 100 --batch_size 32 --lr 1e-3 --use_scheduler True --is_VAE_var True --z_var_size 15 --lambda_BCE 1 --beta 1 --var_second_cnn_block True --var_third_cnn_block False --encoder_var_name mnist_vae_var_2cb_15_classifier_grad_inv_PT_new --freeze_Encoder True --PT_model True --PT_model_EV_classifier True --exp_name mnist_vae_var_2cb_15_grad_inv_PT_new
+ python3 -u main.py --gpu_devices 0 --max_iter 100 --batch_size 32 --lr 1e-3 --use_scheduler True --is_VAE_var True --z_var_size 15 --lambda_BCE 1 --beta 1 --var_second_cnn_block True --var_third_cnn_block False --encoder_var_name mnist_vae_var_2cb_15_classifier_grad_inv_PT_new --freeze_Encoder True --PT_model True --PT_model_EV_classifier True --exp_name mnist_vae_var_2cb_15_grad_inv_PT_new
--- Logging error ---
Traceback (most recent call last):
  File "/gpfslocalsup/pub/anaconda-py3/2020.02/envs/pytorch-gpu-1.6.0/lib/python3.7/logging/__init__.py", line 1025, in emit
    msg = self.format(record)
  File "/gpfslocalsup/pub/anaconda-py3/2020.02/envs/pytorch-gpu-1.6.0/lib/python3.7/logging/__init__.py", line 869, in format
    return fmt.format(record)
  File "/gpfslocalsup/pub/anaconda-py3/2020.02/envs/pytorch-gpu-1.6.0/lib/python3.7/logging/__init__.py", line 611, in format
    s = self.formatMessage(record)
  File "/gpfslocalsup/pub/anaconda-py3/2020.02/envs/pytorch-gpu-1.6.0/lib/python3.7/logging/__init__.py", line 580, in formatMessage
    return self._style.format(record)
  File "/gpfslocalsup/pub/anaconda-py3/2020.02/envs/pytorch-gpu-1.6.0/lib/python3.7/logging/__init__.py", line 422, in format
    return self._fmt % record.__dict__
KeyError: 'asc_time'
Call stack:
  File "main.py", line 329, in <module>
    main(args)
  File "main.py", line 31, in main
    net = SolverClassifier(arguments)
  File "/gpfsdswork/projects/rech/rjg/uiu23ko/Thesis/Pytorch_vanilla_Beta_VAE/solver_classifier.py", line 348, in __init__
    self.test_loader_size))
Message: 'Dataset mnist: train with 60000 samples and 10000 test samples'
Arguments: ()
  0%|          | 0/100.0 [00:00<?, ?it/s]Traceback (most recent call last):
  File "main.py", line 329, in <module>
    main(args)
  File "main.py", line 34, in main
    net.train()
  File "/gpfsdswork/projects/rech/rjg/uiu23ko/Thesis/Pytorch_vanilla_Beta_VAE/solver_classifier.py", line 787, in train
    loss.backward()
AttributeError: 'int' object has no attribute 'backward'
  1%|          | 1/100.0 [00:02<04:13,  2.56s/it]
+ wait
+ echo 'All done !'
