Loading pytorch-gpu/py3/1.6.0
  Loading requirement: gcc/8.3.1 cuda/10.2 nccl/2.6.4-1-cuda
    cudnn/7.6.5.32-cuda-10.2 intel-mkl/2020.1 magma/2.5.3-cuda
    openmpi/4.0.2-cuda
++ sed -n 8p parameters_combinations/mnist_classifier_ratio.txt
+ LINE=
+ echo
+ python3 -u main.py
--- Logging error ---
Traceback (most recent call last):
  File "/gpfslocalsup/pub/anaconda-py3/2020.02/envs/pytorch-gpu-1.6.0/lib/python3.7/logging/__init__.py", line 1025, in emit
    msg = self.format(record)
  File "/gpfslocalsup/pub/anaconda-py3/2020.02/envs/pytorch-gpu-1.6.0/lib/python3.7/logging/__init__.py", line 869, in format
    return fmt.format(record)
  File "/gpfslocalsup/pub/anaconda-py3/2020.02/envs/pytorch-gpu-1.6.0/lib/python3.7/logging/__init__.py", line 611, in format
    s = self.formatMessage(record)
  File "/gpfslocalsup/pub/anaconda-py3/2020.02/envs/pytorch-gpu-1.6.0/lib/python3.7/logging/__init__.py", line 580, in formatMessage
    return self._style.format(record)
  File "/gpfslocalsup/pub/anaconda-py3/2020.02/envs/pytorch-gpu-1.6.0/lib/python3.7/logging/__init__.py", line 422, in format
    return self._fmt % record.__dict__
KeyError: 'asc_time'
Call stack:
  File "main.py", line 321, in <module>
    main(args)
  File "main.py", line 31, in main
    net = SolverClassifier(arguments)
  File "/gpfsdswork/projects/rech/rjg/uiu23ko/Thesis/Pytorch_vanilla_Beta_VAE/solver_classifier.py", line 339, in __init__
    self.test_loader_size))
Message: 'Dataset mnist: train with 60000 samples and 10000 test samples'
Arguments: ()
Traceback (most recent call last):
  File "main.py", line 321, in <module>
    main(args)
  File "main.py", line 31, in main
    net = SolverClassifier(arguments)
  File "/gpfsdswork/projects/rech/rjg/uiu23ko/Thesis/Pytorch_vanilla_Beta_VAE/solver_classifier.py", line 413, in __init__
    if self.use_VAE:
AttributeError: 'SolverClassifier' object has no attribute 'use_VAE'
+ wait
+ echo 'All done !'
